leuleb@rasp:~/Documents $ /usr/bin/python /home/leuleb/Documents/homedrone.py
Traceback (most recent call last):
  File "/usr/lib/python3/dist-packages/serial/serialposix.py", line 322, in open
    self.fd = os.open(self.portstr, os.O_RDWR | os.O_NOCTTY | os.O_NONBLOCK)
              ^^^^^^^^^^^^^^^^^^^^^^^^^^^^^^^^^^^^^^^^^^^^^^^^^^^^^^^^^^^^^^
FileNotFoundError: [Errno 2] No such file or directory: '/dev/serial0'

During handling of the above exception, another exception occurred:

Traceback (most recent call last):
  File "/home/leuleb/Documents/homedrone.py", line 11, in <module>
    vehicle = connect('/dev/serial0', baud=57600, wait_ready=False, heartbeat_timeout=60)
              ^^^^^^^^^^^^^^^^^^^^^^^^^^^^^^^^^^^^^^^^^^^^^^^^^^^^^^^^^^^^^^^^^^^^^^^^^^^
  File "/home/leuleb/.local/lib/python3.11/site-packages/dronekit/__init__.py", line 3158, in connect
    handler = MAVConnection(ip, baud=baud, source_system=source_system, source_component=source_component, use_native=use_native)
              ^^^^^^^^^^^^^^^^^^^^^^^^^^^^^^^^^^^^^^^^^^^^^^^^^^^^^^^^^^^^^^^^^^^^^^^^^^^^^^^^^^^^^^^^^^^^^^^^^^^^^^^^^^^^^^^^^^^
  File "/home/leuleb/.local/lib/python3.11/site-packages/dronekit/mavlink.py", line 130, in __init__
    self.master = mavutil.mavlink_connection(ip, baud=baud, source_system=source_system, source_component=source_component)
                  ^^^^^^^^^^^^^^^^^^^^^^^^^^^^^^^^^^^^^^^^^^^^^^^^^^^^^^^^^^^^^^^^^^^^^^^^^^^^^^^^^^^^^^^^^^^^^^^^^^^^^^^^^
  File "/home/leuleb/.local/lib/python3.11/site-packages/pymavlink/mavutil.py", line 1949, in mavlink_connection
    return mavserial(device,
           ^^^^^^^^^^^^^^^^^
  File "/home/leuleb/.local/lib/python3.11/site-packages/pymavlink/mavutil.py", line 972, in __init__
    raise e
  File "/home/leuleb/.local/lib/python3.11/site-packages/pymavlink/mavutil.py", line 968, in __init__
    self.port = serial.Serial(self.device, 1200, timeout=0,
                ^^^^^^^^^^^^^^^^^^^^^^^^^^^^^^^^^^^^^^^^^^^
  File "/usr/lib/python3/dist-packages/serial/serialutil.py", line 244, in __init__
    self.open()
  File "/usr/lib/python3/dist-packages/serial/serialposix.py", line 325, in open
    raise SerialException(msg.errno, "could not open port {}: {}".format(self._port, msg))
serial.serialutil.SerialException: [Errno 2] could not open port /dev/serial0: [Errno 2] No such file or directory: '/dev/serial0'
